Traceback (most recent call last):
  File "C:\Users\MyBook Z Series\AppData\Local\Packages\PythonSoftwareFoundation.Python.3.13_qbz5n2kfra8p0\LocalCache\local-packages\Python313\site-packages\jupyter_cache\executors\utils.py", line 58, in single_nb_execution
    executenb(
    ~~~~~~~~~^
        nb,
        ^^^
    ...<4 lines>...
        **kwargs,
        ^^^^^^^^^
    )
    ^
  File "C:\Users\MyBook Z Series\AppData\Local\Packages\PythonSoftwareFoundation.Python.3.13_qbz5n2kfra8p0\LocalCache\local-packages\Python313\site-packages\nbclient\client.py", line 1319, in execute
    return NotebookClient(nb=nb, resources=resources, km=km, **kwargs).execute()
           ~~~~~~~~~~~~~~~~~~~~~~~~~~~~~~~~~~~~~~~~~~~~~~~~~~~~~~~~~~~~~~~~~~~^^
  File "C:\Users\MyBook Z Series\AppData\Local\Packages\PythonSoftwareFoundation.Python.3.13_qbz5n2kfra8p0\LocalCache\local-packages\Python313\site-packages\jupyter_core\utils\__init__.py", line 165, in wrapped
    return loop.run_until_complete(inner)
           ~~~~~~~~~~~~~~~~~~~~~~~^^^^^^^
  File "C:\Program Files\WindowsApps\PythonSoftwareFoundation.Python.3.13_3.13.1008.0_x64__qbz5n2kfra8p0\Lib\asyncio\base_events.py", line 719, in run_until_complete
    return future.result()
           ~~~~~~~~~~~~~^^
  File "C:\Users\MyBook Z Series\AppData\Local\Packages\PythonSoftwareFoundation.Python.3.13_qbz5n2kfra8p0\LocalCache\local-packages\Python313\site-packages\nbclient\client.py", line 709, in async_execute
    await self.async_execute_cell(
        cell, index, execution_count=self.code_cells_executed + 1
    )
  File "C:\Users\MyBook Z Series\AppData\Local\Packages\PythonSoftwareFoundation.Python.3.13_qbz5n2kfra8p0\LocalCache\local-packages\Python313\site-packages\nbclient\client.py", line 1062, in async_execute_cell
    await self._check_raise_for_error(cell, cell_index, exec_reply)
  File "C:\Users\MyBook Z Series\AppData\Local\Packages\PythonSoftwareFoundation.Python.3.13_qbz5n2kfra8p0\LocalCache\local-packages\Python313\site-packages\nbclient\client.py", line 918, in _check_raise_for_error
    raise CellExecutionError.from_cell_and_msg(cell, exec_reply_content)
nbclient.exceptions.CellExecutionError: An error occurred while executing the following cell:
------------------
# Mengimport Library yang digunakan dalam prosesnya
import pymysql
import psycopg2
from sqlalchemy import create_engine
import pandas as pd
import matplotlib.pyplot as plt
import seaborn as sns
from scipy import stats
import numpy as np
import base64
import os
from dotenv import load_dotenv
from sklearn.neighbors import LocalOutlierFactor
from sklearn.naive_bayes import GaussianNB
from sklearn.model_selection import train_test_split
from sklearn.metrics import accuracy_score
------------------


[31m---------------------------------------------------------------------------[39m
[31mModuleNotFoundError[39m                       Traceback (most recent call last)
[36mCell[39m[36m [39m[32mIn[1][39m[32m, line 12[39m
[32m     10[39m [38;5;28;01mimport[39;00m[38;5;250m [39m[34;01mbase64[39;00m
[32m     11[39m [38;5;28;01mimport[39;00m[38;5;250m [39m[34;01mos[39;00m
[32m---> [39m[32m12[39m [38;5;28;01mfrom[39;00m[38;5;250m [39m[34;01mdotenv[39;00m[38;5;250m [39m[38;5;28;01mimport[39;00m load_dotenv
[32m     13[39m [38;5;28;01mfrom[39;00m[38;5;250m [39m[34;01msklearn[39;00m[34;01m.[39;00m[34;01mneighbors[39;00m[38;5;250m [39m[38;5;28;01mimport[39;00m LocalOutlierFactor
[32m     14[39m [38;5;28;01mfrom[39;00m[38;5;250m [39m[34;01msklearn[39;00m[34;01m.[39;00m[34;01mnaive_bayes[39;00m[38;5;250m [39m[38;5;28;01mimport[39;00m GaussianNB

[31mModuleNotFoundError[39m: No module named 'dotenv'

